2024-11-29 01:07:10,846 INFO    Thread-132 (_run_job):10301 [wandb_setup.py:_flush():79] Current SDK version is 0.18.7
2024-11-29 01:07:10,847 INFO    Thread-132 (_run_job):10301 [wandb_setup.py:_flush():79] Configure stats pid to 10301
2024-11-29 01:07:10,847 INFO    Thread-132 (_run_job):10301 [wandb_setup.py:_flush():79] Loading settings from /Users/daniekru/.config/wandb/settings
2024-11-29 01:07:10,847 INFO    Thread-132 (_run_job):10301 [wandb_setup.py:_flush():79] Loading settings from /Users/daniekru/Research/lab/minBandit/src/wandb/settings
2024-11-29 01:07:10,847 INFO    Thread-132 (_run_job):10301 [wandb_setup.py:_flush():79] Loading settings from environment variables: {'project': 'minBandit', 'entity': 'ikiru-university-of-oslo', 'root_dir': '/Users/daniekru/Research/lab/minBandit/src', 'run_id': '7bivqu1s', 'sweep_param_path': '/Users/daniekru/Research/lab/minBandit/src/wandb/sweep-4ixq6an5/config-7bivqu1s.yaml', 'sweep_id': '4ixq6an5'}
2024-11-29 01:07:10,847 INFO    Thread-132 (_run_job):10301 [wandb_setup.py:_flush():79] Applying setup settings: {'mode': None, '_disable_service': None}
2024-11-29 01:07:10,847 INFO    Thread-132 (_run_job):10301 [wandb_setup.py:_flush():79] Inferring run settings from compute environment: {'program_relpath': 'src/param_search.py', 'program_abspath': '/Users/daniekru/Research/lab/minBandit/src/param_search.py', 'program': '/Users/daniekru/Research/lab/minBandit/src/param_search.py'}
2024-11-29 01:07:10,847 INFO    Thread-132 (_run_job):10301 [wandb_setup.py:_flush():79] Applying login settings: {}
2024-11-29 01:07:10,847 INFO    Thread-132 (_run_job):10301 [wandb_init.py:_log_setup():533] Logging user logs to /Users/daniekru/Research/lab/minBandit/src/wandb/run-20241129_010710-7bivqu1s/logs/debug.log
2024-11-29 01:07:10,847 INFO    Thread-132 (_run_job):10301 [wandb_init.py:_log_setup():534] Logging internal logs to /Users/daniekru/Research/lab/minBandit/src/wandb/run-20241129_010710-7bivqu1s/logs/debug-internal.log
2024-11-29 01:07:10,847 INFO    Thread-132 (_run_job):10301 [wandb_init.py:init():619] calling init triggers
2024-11-29 01:07:10,848 INFO    Thread-132 (_run_job):10301 [wandb_init.py:init():626] wandb.init called with sweep_config: {'alpha': 1.5055327248510224, 'alpha_lr': -0.862749204858797, 'beta': 3.7438642924818657, 'beta_lr': 5.1098529427157375, 'gain': 0.3182214325706115, 'lr': 7.521104096272815, 'mu': -2.8154524778243477, 'mu_lr': -1.0808769392393351, 'r': 0.2590163306354434, 'r_lr': 0.5815177855189753, 'sigma': 1.6865942694279792, 'sigma_lr': 4.655951778275664, 'threshold': 8.677506266802817, 'w_max': 4.0091895360434195}
config: {}
2024-11-29 01:07:10,848 INFO    Thread-132 (_run_job):10301 [wandb_init.py:init():669] starting backend
2024-11-29 01:07:10,848 INFO    Thread-132 (_run_job):10301 [wandb_init.py:init():673] sending inform_init request
2024-11-29 01:07:10,856 INFO    Thread-132 (_run_job):10301 [backend.py:_multiprocessing_setup():104] multiprocessing start_methods=spawn,fork,forkserver, using: spawn
2024-11-29 01:07:10,856 INFO    Thread-132 (_run_job):10301 [wandb_init.py:init():686] backend started and connected
2024-11-29 01:07:10,864 INFO    Thread-132 (_run_job):10301 [wandb_run.py:_config_callback():1387] config_cb None None {'alpha': 1.5055327248510224, 'alpha_lr': -0.862749204858797, 'beta': 3.7438642924818657, 'beta_lr': 5.1098529427157375, 'gain': 0.3182214325706115, 'lr': 7.521104096272815, 'mu': -2.8154524778243477, 'mu_lr': -1.0808769392393351, 'r': 0.2590163306354434, 'r_lr': 0.5815177855189753, 'sigma': 1.6865942694279792, 'sigma_lr': 4.655951778275664, 'threshold': 8.677506266802817, 'w_max': 4.0091895360434195}
2024-11-29 01:07:10,866 INFO    Thread-132 (_run_job):10301 [wandb_init.py:init():781] updated telemetry
2024-11-29 01:07:10,898 INFO    Thread-132 (_run_job):10301 [wandb_init.py:init():814] communicating run to backend with 90.0 second timeout
2024-11-29 01:10:26,001 INFO    Thread-133 (wrapped_target):10301 [retry.py:__call__():172] Retry attempt failed:
Traceback (most recent call last):
  File "/Users/daniekru/Research/codebase/myenvs/env_cl1/lib/python3.11/site-packages/urllib3/connection.py", line 203, in _new_conn
    sock = connection.create_connection(
           ^^^^^^^^^^^^^^^^^^^^^^^^^^^^^
  File "/Users/daniekru/Research/codebase/myenvs/env_cl1/lib/python3.11/site-packages/urllib3/util/connection.py", line 60, in create_connection
    for res in socket.getaddrinfo(host, port, family, socket.SOCK_STREAM):
               ^^^^^^^^^^^^^^^^^^^^^^^^^^^^^^^^^^^^^^^^^^^^^^^^^^^^^^^^^^
  File "/opt/homebrew/Cellar/python@3.11/3.11.10/Frameworks/Python.framework/Versions/3.11/lib/python3.11/socket.py", line 974, in getaddrinfo
    for res in _socket.getaddrinfo(host, port, family, type, proto, flags):
               ^^^^^^^^^^^^^^^^^^^^^^^^^^^^^^^^^^^^^^^^^^^^^^^^^^^^^^^^^^^
socket.gaierror: [Errno 8] nodename nor servname provided, or not known

The above exception was the direct cause of the following exception:

Traceback (most recent call last):
  File "/Users/daniekru/Research/codebase/myenvs/env_cl1/lib/python3.11/site-packages/urllib3/connectionpool.py", line 790, in urlopen
    response = self._make_request(
               ^^^^^^^^^^^^^^^^^^^
  File "/Users/daniekru/Research/codebase/myenvs/env_cl1/lib/python3.11/site-packages/urllib3/connectionpool.py", line 491, in _make_request
    raise new_e
  File "/Users/daniekru/Research/codebase/myenvs/env_cl1/lib/python3.11/site-packages/urllib3/connectionpool.py", line 467, in _make_request
    self._validate_conn(conn)
  File "/Users/daniekru/Research/codebase/myenvs/env_cl1/lib/python3.11/site-packages/urllib3/connectionpool.py", line 1092, in _validate_conn
    conn.connect()
  File "/Users/daniekru/Research/codebase/myenvs/env_cl1/lib/python3.11/site-packages/urllib3/connection.py", line 611, in connect
    self.sock = sock = self._new_conn()
                       ^^^^^^^^^^^^^^^^
  File "/Users/daniekru/Research/codebase/myenvs/env_cl1/lib/python3.11/site-packages/urllib3/connection.py", line 210, in _new_conn
    raise NameResolutionError(self.host, self, e) from e
urllib3.exceptions.NameResolutionError: <urllib3.connection.HTTPSConnection object at 0x11d8de750>: Failed to resolve 'api.wandb.ai' ([Errno 8] nodename nor servname provided, or not known)

The above exception was the direct cause of the following exception:

Traceback (most recent call last):
  File "/Users/daniekru/Research/codebase/myenvs/env_cl1/lib/python3.11/site-packages/requests/adapters.py", line 486, in send
    resp = conn.urlopen(
           ^^^^^^^^^^^^^
  File "/Users/daniekru/Research/codebase/myenvs/env_cl1/lib/python3.11/site-packages/urllib3/connectionpool.py", line 844, in urlopen
    retries = retries.increment(
              ^^^^^^^^^^^^^^^^^^
  File "/Users/daniekru/Research/codebase/myenvs/env_cl1/lib/python3.11/site-packages/urllib3/util/retry.py", line 515, in increment
    raise MaxRetryError(_pool, url, reason) from reason  # type: ignore[arg-type]
    ^^^^^^^^^^^^^^^^^^^^^^^^^^^^^^^^^^^^^^^^^^^^^^^^^^^
urllib3.exceptions.MaxRetryError: HTTPSConnectionPool(host='api.wandb.ai', port=443): Max retries exceeded with url: /graphql (Caused by NameResolutionError("<urllib3.connection.HTTPSConnection object at 0x11d8de750>: Failed to resolve 'api.wandb.ai' ([Errno 8] nodename nor servname provided, or not known)"))

During handling of the above exception, another exception occurred:

Traceback (most recent call last):
  File "/Users/daniekru/Research/codebase/myenvs/env_cl1/lib/python3.11/site-packages/wandb/sdk/lib/retry.py", line 131, in __call__
    result = self._call_fn(*args, **kwargs)
             ^^^^^^^^^^^^^^^^^^^^^^^^^^^^^^
  File "/Users/daniekru/Research/codebase/myenvs/env_cl1/lib/python3.11/site-packages/wandb/sdk/internal/internal_api.py", line 400, in execute
    return self.client.execute(*args, **kwargs)  # type: ignore
           ^^^^^^^^^^^^^^^^^^^^^^^^^^^^^^^^^^^^
  File "/Users/daniekru/Research/codebase/myenvs/env_cl1/lib/python3.11/site-packages/wandb/vendor/gql-0.2.0/wandb_gql/client.py", line 52, in execute
    result = self._get_result(document, *args, **kwargs)
             ^^^^^^^^^^^^^^^^^^^^^^^^^^^^^^^^^^^^^^^^^^^
  File "/Users/daniekru/Research/codebase/myenvs/env_cl1/lib/python3.11/site-packages/wandb/vendor/gql-0.2.0/wandb_gql/client.py", line 60, in _get_result
    return self.transport.execute(document, *args, **kwargs)
           ^^^^^^^^^^^^^^^^^^^^^^^^^^^^^^^^^^^^^^^^^^^^^^^^^
  File "/Users/daniekru/Research/codebase/myenvs/env_cl1/lib/python3.11/site-packages/wandb/sdk/lib/gql_request.py", line 58, in execute
    request = self.session.post(self.url, **post_args)
              ^^^^^^^^^^^^^^^^^^^^^^^^^^^^^^^^^^^^^^^^
  File "/Users/daniekru/Research/codebase/myenvs/env_cl1/lib/python3.11/site-packages/requests/sessions.py", line 637, in post
    return self.request("POST", url, data=data, json=json, **kwargs)
           ^^^^^^^^^^^^^^^^^^^^^^^^^^^^^^^^^^^^^^^^^^^^^^^^^^^^^^^^^
  File "/Users/daniekru/Research/codebase/myenvs/env_cl1/lib/python3.11/site-packages/requests/sessions.py", line 589, in request
    resp = self.send(prep, **send_kwargs)
           ^^^^^^^^^^^^^^^^^^^^^^^^^^^^^^
  File "/Users/daniekru/Research/codebase/myenvs/env_cl1/lib/python3.11/site-packages/requests/sessions.py", line 703, in send
    r = adapter.send(request, **kwargs)
        ^^^^^^^^^^^^^^^^^^^^^^^^^^^^^^^
  File "/Users/daniekru/Research/codebase/myenvs/env_cl1/lib/python3.11/site-packages/requests/adapters.py", line 519, in send
    raise ConnectionError(e, request=request)
requests.exceptions.ConnectionError: HTTPSConnectionPool(host='api.wandb.ai', port=443): Max retries exceeded with url: /graphql (Caused by NameResolutionError("<urllib3.connection.HTTPSConnection object at 0x11d8de750>: Failed to resolve 'api.wandb.ai' ([Errno 8] nodename nor servname provided, or not known)"))
2024-11-29 01:34:51,193 INFO    Thread-1 (_heartbeat):10301 [retry.py:__call__():172] Retry attempt failed:
Traceback (most recent call last):
  File "/Users/daniekru/Research/codebase/myenvs/env_cl1/lib/python3.11/site-packages/urllib3/connection.py", line 203, in _new_conn
    sock = connection.create_connection(
           ^^^^^^^^^^^^^^^^^^^^^^^^^^^^^
  File "/Users/daniekru/Research/codebase/myenvs/env_cl1/lib/python3.11/site-packages/urllib3/util/connection.py", line 60, in create_connection
    for res in socket.getaddrinfo(host, port, family, socket.SOCK_STREAM):
               ^^^^^^^^^^^^^^^^^^^^^^^^^^^^^^^^^^^^^^^^^^^^^^^^^^^^^^^^^^
  File "/opt/homebrew/Cellar/python@3.11/3.11.10/Frameworks/Python.framework/Versions/3.11/lib/python3.11/socket.py", line 974, in getaddrinfo
    for res in _socket.getaddrinfo(host, port, family, type, proto, flags):
               ^^^^^^^^^^^^^^^^^^^^^^^^^^^^^^^^^^^^^^^^^^^^^^^^^^^^^^^^^^^
socket.gaierror: [Errno 8] nodename nor servname provided, or not known

The above exception was the direct cause of the following exception:

Traceback (most recent call last):
  File "/Users/daniekru/Research/codebase/myenvs/env_cl1/lib/python3.11/site-packages/urllib3/connectionpool.py", line 790, in urlopen
    response = self._make_request(
               ^^^^^^^^^^^^^^^^^^^
  File "/Users/daniekru/Research/codebase/myenvs/env_cl1/lib/python3.11/site-packages/urllib3/connectionpool.py", line 491, in _make_request
    raise new_e
  File "/Users/daniekru/Research/codebase/myenvs/env_cl1/lib/python3.11/site-packages/urllib3/connectionpool.py", line 467, in _make_request
    self._validate_conn(conn)
  File "/Users/daniekru/Research/codebase/myenvs/env_cl1/lib/python3.11/site-packages/urllib3/connectionpool.py", line 1092, in _validate_conn
    conn.connect()
  File "/Users/daniekru/Research/codebase/myenvs/env_cl1/lib/python3.11/site-packages/urllib3/connection.py", line 611, in connect
    self.sock = sock = self._new_conn()
                       ^^^^^^^^^^^^^^^^
  File "/Users/daniekru/Research/codebase/myenvs/env_cl1/lib/python3.11/site-packages/urllib3/connection.py", line 210, in _new_conn
    raise NameResolutionError(self.host, self, e) from e
urllib3.exceptions.NameResolutionError: <urllib3.connection.HTTPSConnection object at 0x11d770f10>: Failed to resolve 'api.wandb.ai' ([Errno 8] nodename nor servname provided, or not known)

The above exception was the direct cause of the following exception:

Traceback (most recent call last):
  File "/Users/daniekru/Research/codebase/myenvs/env_cl1/lib/python3.11/site-packages/requests/adapters.py", line 486, in send
    resp = conn.urlopen(
           ^^^^^^^^^^^^^
  File "/Users/daniekru/Research/codebase/myenvs/env_cl1/lib/python3.11/site-packages/urllib3/connectionpool.py", line 844, in urlopen
    retries = retries.increment(
              ^^^^^^^^^^^^^^^^^^
  File "/Users/daniekru/Research/codebase/myenvs/env_cl1/lib/python3.11/site-packages/urllib3/util/retry.py", line 515, in increment
    raise MaxRetryError(_pool, url, reason) from reason  # type: ignore[arg-type]
    ^^^^^^^^^^^^^^^^^^^^^^^^^^^^^^^^^^^^^^^^^^^^^^^^^^^
urllib3.exceptions.MaxRetryError: HTTPSConnectionPool(host='api.wandb.ai', port=443): Max retries exceeded with url: /graphql (Caused by NameResolutionError("<urllib3.connection.HTTPSConnection object at 0x11d770f10>: Failed to resolve 'api.wandb.ai' ([Errno 8] nodename nor servname provided, or not known)"))

During handling of the above exception, another exception occurred:

Traceback (most recent call last):
  File "/Users/daniekru/Research/codebase/myenvs/env_cl1/lib/python3.11/site-packages/wandb/sdk/lib/retry.py", line 131, in __call__
    result = self._call_fn(*args, **kwargs)
             ^^^^^^^^^^^^^^^^^^^^^^^^^^^^^^
  File "/Users/daniekru/Research/codebase/myenvs/env_cl1/lib/python3.11/site-packages/wandb/sdk/internal/internal_api.py", line 400, in execute
    return self.client.execute(*args, **kwargs)  # type: ignore
           ^^^^^^^^^^^^^^^^^^^^^^^^^^^^^^^^^^^^
  File "/Users/daniekru/Research/codebase/myenvs/env_cl1/lib/python3.11/site-packages/wandb/vendor/gql-0.2.0/wandb_gql/client.py", line 52, in execute
    result = self._get_result(document, *args, **kwargs)
             ^^^^^^^^^^^^^^^^^^^^^^^^^^^^^^^^^^^^^^^^^^^
  File "/Users/daniekru/Research/codebase/myenvs/env_cl1/lib/python3.11/site-packages/wandb/vendor/gql-0.2.0/wandb_gql/client.py", line 60, in _get_result
    return self.transport.execute(document, *args, **kwargs)
           ^^^^^^^^^^^^^^^^^^^^^^^^^^^^^^^^^^^^^^^^^^^^^^^^^
  File "/Users/daniekru/Research/codebase/myenvs/env_cl1/lib/python3.11/site-packages/wandb/sdk/lib/gql_request.py", line 58, in execute
    request = self.session.post(self.url, **post_args)
              ^^^^^^^^^^^^^^^^^^^^^^^^^^^^^^^^^^^^^^^^
  File "/Users/daniekru/Research/codebase/myenvs/env_cl1/lib/python3.11/site-packages/requests/sessions.py", line 637, in post
    return self.request("POST", url, data=data, json=json, **kwargs)
           ^^^^^^^^^^^^^^^^^^^^^^^^^^^^^^^^^^^^^^^^^^^^^^^^^^^^^^^^^
  File "/Users/daniekru/Research/codebase/myenvs/env_cl1/lib/python3.11/site-packages/requests/sessions.py", line 589, in request
    resp = self.send(prep, **send_kwargs)
           ^^^^^^^^^^^^^^^^^^^^^^^^^^^^^^
  File "/Users/daniekru/Research/codebase/myenvs/env_cl1/lib/python3.11/site-packages/requests/sessions.py", line 703, in send
    r = adapter.send(request, **kwargs)
        ^^^^^^^^^^^^^^^^^^^^^^^^^^^^^^^
  File "/Users/daniekru/Research/codebase/myenvs/env_cl1/lib/python3.11/site-packages/requests/adapters.py", line 519, in send
    raise ConnectionError(e, request=request)
requests.exceptions.ConnectionError: HTTPSConnectionPool(host='api.wandb.ai', port=443): Max retries exceeded with url: /graphql (Caused by NameResolutionError("<urllib3.connection.HTTPSConnection object at 0x11d770f10>: Failed to resolve 'api.wandb.ai' ([Errno 8] nodename nor servname provided, or not known)"))
2024-11-29 01:34:55,731 INFO    Thread-132 (_run_job):10301 [wandb_init.py:init():867] starting run threads in backend
2024-11-29 01:34:55,863 INFO    Thread-132 (_run_job):10301 [wandb_run.py:_console_start():2456] atexit reg
2024-11-29 01:34:55,863 INFO    Thread-132 (_run_job):10301 [wandb_run.py:_redirect():2305] redirect: wrap_raw
2024-11-29 01:34:55,863 INFO    Thread-132 (_run_job):10301 [wandb_run.py:_redirect():2370] Wrapping output streams.
2024-11-29 01:34:55,863 INFO    Thread-132 (_run_job):10301 [wandb_run.py:_redirect():2395] Redirects installed.
2024-11-29 01:34:55,863 INFO    Thread-132 (_run_job):10301 [wandb_init.py:init():911] run started, returning control to user process
2024-11-29 01:42:45,045 INFO    Thread-132 (_run_job):10301 [wandb_run.py:_finish():2155] finishing run ikiru-university-of-oslo/minBandit/7bivqu1s
2024-11-29 01:42:45,046 INFO    Thread-132 (_run_job):10301 [wandb_run.py:_atexit_cleanup():2420] got exitcode: 0
2024-11-29 01:42:45,047 INFO    Thread-132 (_run_job):10301 [wandb_run.py:_restore():2402] restore
2024-11-29 01:42:45,047 INFO    Thread-132 (_run_job):10301 [wandb_run.py:_restore():2408] restore done
2024-11-29 01:42:47,303 INFO    Thread-132 (_run_job):10301 [wandb_run.py:_footer_history_summary_info():3960] rendering history
2024-11-29 01:42:47,304 INFO    Thread-132 (_run_job):10301 [wandb_run.py:_footer_history_summary_info():3992] rendering summary
2024-11-29 01:42:47,322 INFO    Thread-132 (_run_job):10301 [wandb_run.py:_footer_sync_info():3921] logging synced files
